Workbook

Sheet Dados_Projeto
C1: Dados Basicos do Projeto | G1: Dados do Indutor Acoplado | K1: LEGENDA
C2: Parametro | D2: Valor | E2: Unidade | G2: Modelo | H2: =Calculo_Flyback!O4 -> T106-26 | L2: Dado Manual do Usuário
C3: V microcontrolador | D3: 5 | E3: V | G3: Lm | H3: =Calculo_FlyBack_Simples!M22 -> 450000 | I3: uH | L3: Dado Calculado
C4: V in(max) | D4: 12 | E4: V | G4: Fio | H4: =Calculo_FlyBack_Simples!M27 -> 24 | I4: AWG
C5: V in rms | D5: =D4 -> 12 | E5: V | G5: Voltas N1 p/ Fio | H5: =Calculo_FlyBack_Simples!M23 -> 69 | I5: Voltas
C6: V in(min) | D6: =D4 -> 12 | E6: V | G6: Qntd Fios N1 | H6: =Calculo_FlyBack_Simples!M24 -> 1 | I6: Fios
C7: V out | D7: 5 | E7: V | G7: Qntd Fios N2 | H7: =Calculo_FlyBack_Simples!M28 -> 12.32 | I7: Fios
C8: R out | D8: 10 | E8: Ω | G8: Total Voltas | H8: =Calculo_FlyBack_Simples!M26 -> 1 | I8: Voltas
C9: L Trafo Requerido | D9: 450 | E9: uH | G9: N2/N1 | H9: =Calculo_FlyBack_Simples!M7 -> 0.17857143 | I9: Constante
C10: L Trafo Requerido | D10: =D9/1000000 -> 0.00045 | E10: H | G10: Capacitor Comercial | H10: =Calculo_FlyBack_Simples!Q29 -> 3.3e-05 | I10: Faraday
C11: N1/N2 | D11: 4.5 | E11: - | G11: Capacitor Comercial | H11: =H10*1000000 -> 33 | I11: uF
C12: N1/N2 | D12: 5.6 | E12: -
C13: Escolha o Mosfet | D13: IRF640
C14: Frequência | D14: 62.5 | E14: kH | G14: Valor Medido | H14: 1.495 | I14: mH
C15: Frequência | D15: =D14*1000 -> 62500 | E15: H | G15: Voltas | H15: 20
C16: β(SAT) | D16: 10 | G16: Nano Henry | H16: =H14*1000000 -> 1495000
C17: I min gate Drive (IC) | D17: 1 | E17: mA | G17: Al Medido | H17: =H16/(H15*H15) -> 3737.5 | I17: nH/N^2
C18: I min gate Drive (IC) | D18: =D17/1000 -> 0.001 | E18: A
C19: I máx Gate Mosfet 1% | D19: =IF(D13="P75NF75",Estudo_Mosfet!G24,Estudo_Mosfet!O24) -> 0.254 | E19: A | G19: Valor Medido | H19: 0.013 | I19: mH
C20: I máx Gate Mosfet 1% | D20: =D19*1000 -> 254 | E20: mA | G20: Voltas | H20: 10
C21: Rb Opto | D21: =Estudo_Drive!S29 -> 18000 | E21: Ω | G21: Nano Henry | H21: =H19*1000000 -> 13000
C22: R1 Gate Drive | D22: =Estudo_Drive!S25 -> 4700 | E22: Ω | G22: Al Medido | H22: =H21/(H20*H20) -> 130 | I22: nH/N^2
C23: R2 Gate Drive | D23: =Estudo_Drive!S21 -> 470 | E23: Ω
C24: R3 Gate Drive / Rg Mosfet | D24: =Estudo_Drive!S5 -> 47 | E24: Ω
C25: Definições para o Flyback
C26: ∆ Vo | D26: 1 | E26: %
C27: V diodo | D27: 0.7 | E27: V
C28: Duty Cicle | D28: 0.7 | E28: num
C29: B max | D29: 0.25 | E29: Tesla
C30: Tipo da Condução | D30: Contínuo
C31: Tipo do Indutor | D31: Toroidal
C32: Tipo da Condução | D32: =Calculo_Flyback!F33 -> Qual Fio
C33: Fio AWG | D33: =Calculo_FlyBack_Simples!M27 -> 24 | E33: AWG

Sheet Estudo_Drive
C1: =Estudo_Mosfet!G16 -> 1.39 | N1: aaaaaaaaaaaaaaaaaaaa | O1: aaaaaa | P1: aaaaa | R1: Vcc Arduino | S1: 5 | U1: mA
C2: =Estudo_Mosfet!O16 -> 1.6666667 | R2: Vcc | S2: =Dados_Projeto!D4 -> 12 | T2: V
B3: IB3 | C3: =C2*1000 -> 1666.6667 | D3: mA | J3: Ib Entrada | K3: 2 | L3: mA | R3: Ig | S3: =Dados_Projeto!D19 -> 0.254 | T3: A | U3: =S3*1000 -> 254
B4: IB3 | C4: =Dados_Projeto!D18 -> 0.001 | D4: A | J4: Ib Entrada | K4: =K3/1000 -> 0.002 | L4: A | R4: R3 | S4: =S2/S3 -> 47.244094 | T4: Ω
B5: β(SAT) | C5: =Dados_Projeto!D16 -> 10 | D5: num | J5: V microcontrolador | K5: =Dados_Projeto!D3 -> 5 | L5: V | R5: R3 cmc | S5: =INDEX(Resistores_Comerciais!A:A,MATCH("Sim",Resistores_Comerciais!D:D,0)) -> 47 | T5: Ω
B6: IC3 | C6: =C5*C3 -> 16666.667 | D6: mA | J6: R1 Rb | K6: =K5/(K3/1000) -> 2500 | L6: Ohm
B7: IC3 | C7: =C6/1000 -> 16.666667 | D7: A | J7: Resistor cmc | K7: =INDEX(Tabela2[Resistencia],MATCH("Sim",#REF!,0)) -> #REF! | L7: Ohm | R7: Ec | S7: =(1/2)*1*10^(-9)*S2^2 -> 7.2e-08 | T7: J
B8: Vdd | C8: =Dados_Projeto!D5 -> 12 | D8: V | R8: Ec | S8: =S7*1000000000 -> 72 | T8: nJ
B9: R3 | C9: =C8/C7 -> 0.72 | D9: Ω | R9: T esquisito | S9: =S4*1*10^(-9) -> 4.7244094e-08 | T9: s
B10: R3 cmc | C10: =INDEX(Resistores_Comerciais!A:A,MATCH("Sim",Resistores_Comerciais!#REF!,0)) -> #REF! | D10: Ω | R10: T esquisito | S10: =S9*1000000000 -> 47.244094 | T10: ns
B11: Ciss | C11: 1 | D11: nF | J11: R1 do Drive usando BC337 e ib = 2 mA | N11: R2 do Drive usando BC337 e ib = 2 mA | R11: t | S11: =5*S10 -> 236.22047 | T11: ns
B12: E | C12: =1/2*C11*(10^-9)*C8^2 -> 7.2e-08 | D12: J | J12: Relação Ib/Ic | K12: 10 | N12: Relação Ib/Ic | O12: 10
B13: E | C13: =C12*10^9 -> 72 | D13: J | J13: Ib Q1 | K13: =K3 -> 2 | L13: mA | N13: Ib Q1 | O13: =K14 -> 20 | P13: mA | R13: f | S13: =Dados_Projeto!D15 -> 62500 | T13: hz
B14: t | C14: =C11*(10^-9)*C9 -> 7.2e-10 | D14: s | J14: Ic Q1 | K14: =K3*10 -> 20 | L14: mA | N14: Ic Q1 | O14: =O13*10 -> 200 | P14: mA | R14: T | S14: =1/S13 -> 1.6e-05 | T14: s
B15: t | C15: =C14*1000000000 -> 0.72 | D15: ns | J15: Ic Q1 | K15: =K14/1000 -> 0.02 | L15: A | N15: Ic Q1 | O15: =O14/1000 -> 0.2 | P15: A | R15: T | S15: =S14*1000000 -> 16 | T15: us
B16: t | C16: =C14*5 -> 3.6e-09 | D16: s | J16: Vdd = vcc | K16: =Dados_Projeto!D5 -> 12 | L16: V | N16: Vdd = vcc | O16: =K16 -> 12 | P16: V
B17: t | C17: =C16*1000000000 -> 3.6 | D17: ns | J17: Rc Q1/ Rb Q2 | K17: =K16/K15 -> 600 | L17: Ohm | N17: Rc Q1/ Rb Q2 | O17: =O16/O15 -> 60 | P17: Ohm | R17: P | S17: =S8/S15 -> 4.5 | T17: mW
J18: Rc Q1/ Rb Q2 cmc | K18: =INDEX(Tabela2[Resistencia],MATCH("Sim",#REF!,0)) -> #REF! | L18: Ohm | N18: Rc Q1/ Rb Q2 cmc | O18: =INDEX(Tabela2[Resistencia],MATCH("Sim",Resistores_Comerciais!#REF!,0)) -> #REF! | P18: Ohm
B19: T | C19: =1/Dados_Projeto!D15 -> 1.6e-05 | D19: s | J19: Ic Q1 = Ib Q2 | K19: =K16/K18 -> #REF! | L19: A | N19: Ic Q1 = Ib Q2 | O19: =O16/O18 -> #REF! | P19: A | R19: IB3 = IR2 | S19: =S3/10 -> 0.0254 | T19: A | U19: =S19*1000 -> 25.4
B20: T | C20: =C19*1000000000 -> 16000 | D20: ns | J20: Ic Q1 = Ib Q2 | K20: =K19*1000 -> #REF! | L20: mA | N20: Ic Q1 = Ib Q2 | O20: =O19*1000 -> #REF! | P20: mA | R20: R2 | S20: =(S2-0.7)/S19 -> 444.88189 | T20: Ω | U20: Menor Melhor
B21: Pmed | C21: =C12/C19 -> 0.0045 | D21: W | R21: R2 cmc | S21: =INDEX(Resistores_Comerciais!A:A,MATCH("Sim",Resistores_Comerciais!G:G,0)) -> 470 | T21: Ω
B22: Pmed | C22: =ROUND(C21*1000,2) -> 4.5 | D22: mW
J23: R1 do Drive usando Opto | N23: R2 do Drive usando Opto | R23: Ib2 = Ic2/10 | S23: =S19/10 -> 0.00254 | T23: A | U23: =S23*1000 -> 2.54
B24: IB3 | C24: =C6/C5 -> 1666.6667 | D24: mA | J24: Relação Ib/Ic | K24: 10 | N24: Relação Ib/Ic | O24: 10 | R24: R1 | S24: =(S2-0.7)/S23 -> 4448.8189 | T24: Ω
B25: IB3 | C25: =C24/1000 -> 1.6666667 | D25: A | J25: Ib Q1 | K25: =Estudo_OptoAcoplador!E22*1000 -> 5 | L25: mA | N25: Ib Q1 | O25: =K26 -> 0.5 | P25: mA | R25: R1 cmc | S25: =INDEX(Resistores_Comerciais!A:A,MATCH("Sim",Resistores_Comerciais!J:J,0)) -> 4700 | T25: Ω
B26: R2 | C26: =(C8-0.7)/C25 -> 6.78 | D26: Ω | J26: Ic Q1 | K26: =K25/K24 -> 0.5 | L26: mA | N26: Ic Q1 | O26: =O25*10 -> 5 | P26: mA
B27: R2 cmc | C27: =INDEX(Resistores_Comerciais!A:A,MATCH("Sim",Resistores_Comerciais!#REF!,0)) -> #REF! | D27: Ω | J27: Ic Q1 | K27: =K26/1000 -> 0.0005 | L27: A | N27: Ic Q1 | O27: =O26/1000 -> 0.005 | P27: A | R27: Ib2 = Ic2/10 | S27: =S23/10 -> 0.000254 | T27: A | U27: =S27*1000 -> 0.254
J28: Vdd = vcc | K28: =K16 -> 12 | L28: V | N28: Vdd = vcc | O28: =O16 -> 12 | P28: V | R28: R1 | S28: =(S1-0.7)/S27 -> 16929.134 | T28: Ω
B29: IC2 | C29: =C24 -> 1666.6667 | D29: mA | J29: Rc Q1/ Rb Q2 | K29: =K28/K27 -> 24000 | L29: Ohm | N29: Rc Q1/ Rb Q2 | O29: =O28/O27 -> 2400 | P29: Ohm | R29: R1 cmc | S29: =INDEX(Resistores_Comerciais!A:A,MATCH("Sim",Resistores_Comerciais!M:M,0)) -> 18000 | T29: Ω
B30: IC2 | C30: =C25 -> 1.6666667 | D30: A | J30: Rc Q1/ Rb Q2 cmc | K30: =INDEX(Tabela2[Resistencia],MATCH("Sim",#REF!,0)) -> #REF! | L30: Ohm | N30: Rc Q1/ Rb Q2 cmc | O30: =INDEX(Tabela2[Resistencia],MATCH("Sim",#REF!,0)) -> #REF! | P30: Ohm
B31: IB2 | C31: =C29/C5 -> 166.66667 | D31: mA | J31: Ic Q1 = Ib Q2 | K31: =K28/K30 -> #REF! | L31: A | N31: Ic Q1 = Ib Q2 | O31: =O28/O30 -> #REF! | P31: A
B32: IB2 | C32: =C31/1000 -> 0.16666667 | D32: A | J32: Ic Q1 = Ib Q2 | K32: =K31*1000 -> #REF! | L32: mA | N32: Ic Q1 = Ib Q2 | O32: =O31*1000 -> #REF! | P32: mA
B34: R1 | C34: =(C8-0.7)/C32 -> 67.8 | D34: Ω
B35: R1 cmc | C35: =INDEX(Resistores_Comerciais!A:A,MATCH("Sim",Resistores_Comerciais!#REF!,0)) -> #REF! | D35: Ω

Sheet Estudo_Mosfet
C3: MOSFET P75NF75 | K3: MOSFET IRF540
C5: Circ. Teste Datasheet | D5: Parâmetro | E5: Descrição | F5: Condição | G5: Valor Típico | H5: Valor Máximo | I5: Unidade | K5: Circ. Teste Datasheet | L5: Parâmetro | M5: Descrição | N5: Condição | O5: Valor Típico | P5: Valor Máximo | Q5: Unidade
D6: tD(ON) | E6: Turn-On Delay Time | F6: VDD=37,5V, ID=45A, VGS=10V, RG=4,7Ω | G6: 25 | I6: ns | L6: tD(ON) | M6: Turn-On Delay Time | N6: VDD=37,5V, ID=45A, VGS=10V, RG=4,7Ω | O6: 8 | Q6: ns
D7: tR | E7: Turn-On Rise Time | F7: VDD=37,5V, ID=45A, VGS=10V, RG=4,7Ω | G7: 100 | I7: ns | L7: tR | M7: Turn-On Rise Time | N7: VDD=37,5V, ID=45A, VGS=10V, RG=4,7Ω | O7: 39 | Q7: ns
D8: tD(OFF) | E8: Turn-Off Delay Time | F8: VGS=10V, RG=4,7Ω | G8: 66 | I8: ns | L8: tD(OFF) | M8: Turn-Off Delay Time | N8: VGS=10V, RG=4,7Ω | O8: 26 | Q8: ns
D9: tF | E9: Turn-Off Fall Time | F9: VGS=10V, RG=4,7Ω | G9: 30 | I9: ns | L9: tF | M9: Turn-Off Fall Time | N9: VGS=10V, RG=4,7Ω | O9: 24 | Q9: ns
D10: Qg | E10: Total Gate Charge | F10: VDS=60V, VGS=10V, ID=80A | G10: 117 | H10: 160 | I10: nC | L10: Qg | M10: Total Gate Charge | N10: VDS=60V, VGS=10V, ID=80A | O10: 65 | Q10: nC
D11: Qgs | E11: Gate-Source Charge | F11: VDS=60V, VGS=10V, ID=80A | G11: 27 | I11: nC | L11: Qgs | M11: Gate-Source Charge | N11: VDS=60V, VGS=10V, ID=80A | O11: 10 | Q11: nC
D12: Qgd | E12: Gate-Drain Charge | F12: VDS=60V, VGS=10V, ID=80A | G12: 47 | I12: nC | L12: Qgd | M12: Gate-Drain Charge | N12: VDS=60V, VGS=10V, ID=80A | O12: 29 | Q12: nC
D13: Ciss | E13: Imput Capacitance | F13: VGS = 0 V, VDS = 25 V f = 1MHz | G13: 3700 | I13: pF | L13: Ciss | M13: Imput Capacitance | N13: VGS = 0 V, VDS = 25 V f = 1MHz | O13: 890 | P13: 1187 | Q13: pF
C15: Dados Calculados | D15: Qg Medio | E15: Total Gate Charge | F15: =F10 -> VDS=60V, VGS=10V, ID=80A | G15: =ROUNDUP((G10+H10)/2,0) -> 139 | I15: nC | K15: Dados Calculados | L15: Qg Medio | M15: Total Gate Charge | N15: =N10 -> VDS=60V, VGS=10V, ID=80A | O15: 65 | Q15: nC
D16: Ig Max | E16: Corrente no Gate Max | F16: =F11 -> VDS=60V, VGS=10V, ID=80A | G16: =G15/G7 -> 1.39 | I16: A | L16: Ig Max | M16: Corrente no Gate Max | N16: =N11 -> VDS=60V, VGS=10V, ID=80A | O16: =O15/O7 -> 1.6666667 | Q16: A
D17: p% Pulso | E17: Porcentagem de Pulso | G17: 0.8 | I17: % | L17: p% Pulso | M17: Porcentagem de Pulso | O17: 1.6 | Q17: %
D18: F tr | E18: Frequencia de Trabalho | G18: =Dados_Projeto!D14 -> 62.5 | I18: kH | L18: F tr | M18: Frequencia de Trabalho | O18: =Dados_Projeto!D14 -> 62.5 | Q18: kH
D19: F tr | E19: Frequencia de Trabalho | G19: =G18*1000 -> 62500 | I19: H | L19: F tr | M19: Frequencia de Trabalho | O19: =O18*1000 -> 62500 | Q19: H
D20: T tr | E20: Periodo de Trabalho | G20: =1/G19 -> 1.6e-05 | H20: =Dados_Projeto!D16 -> 10 | I20: s | L20: T tr | M20: Periodo de Trabalho | O20: =1/O19 -> 1.6e-05 | Q20: s
D21: T tr | E21: Periodo de Trabalho | G21: =G20*1000000000 -> 16000 | I21: ns | L21: T tr | M21: Periodo de Trabalho | O21: =O20*1000000000 -> 16000 | Q21: ns
D22: T pulso | E22: T Pulso para não Aquecer o Mosfet + que 1% do Tr | G22: =G20*G17% -> 1.28e-07 | I22: s | L22: T pulso | M22: T Pulso para não Aquecer o Mosfet + que 1% do Tr | O22: =O20*O17% -> 2.56e-07 | Q22: s
D23: T pulso | E23: T Pulso para não Aquecer o Mosfet + que 1% do Tr | G23: =G22*1000000000 -> 128 | I23: ns | L23: T pulso | M23: T Pulso para não Aquecer o Mosfet + que 1% do Tr | O23: =O22*1000000000 -> 256 | Q23: ns
D24: Ig Pulso | E24: Corrente de Gate para esse pulso de 1% de Tr | G24: =ROUND(G15/G23,3) -> 1.086 | H24: =G16 -> 1.39 | I24: A | L24: Ig Pulso | M24: Corrente de Gate para esse pulso de 1% de Tr | O24: =ROUND(O15/O23,3) -> 0.254 | P24: =O16 -> 1.6666667 | Q24: A
D25: Vcc drive | E25: Tensão de entrada ou do drive que irá adionar o mosfet | G25: =Dados_Projeto!D5 -> 12 | I25: V | L25: Vcc drive | M25: Tensão de entrada ou do drive que irá adionar o mosfet | O25: =G25 -> 12 | Q25: V
D26: Rg | E26: ="R gate do Mosfet para acionar em "&G24&" A" -> R gate do Mosfet para acionar em 1,086 A | G26: =ROUND(G25/G24,2) -> 11.05 | I26: Ohm | L26: Rg | M26: ="R gate do Mosfet para acionar em "&O24&" A" -> R gate do Mosfet para acionar em 0,254 A | O26: =ROUND(O25/O24,2) -> 47.24 | Q26: Ohm
D27: Rg cmc | E27: R gate do Mosfet Comercial | G27: =INDEX(Resistores_Comerciais!A:A,MATCH("Sim",Resistores_Comerciais!D:D,0)) -> 47 | I27: Ohm | L27: Rg cmc | M27: R gate do Mosfet Comercial | O27: =INDEX(Resistores_Comerciais!A:A,MATCH("Sim",Resistores_Comerciais!D:D,0)) -> 47 | Q27: Ohm
E34: perda de potencia no mosfet
C35: Link youtube | D35: MOSFET: Acionamento do gate, resistência do gate | E35: MOSFET: Por que usar a resistência de gate?

Sheet Calculo_FlyBack_Simples
G1: AAAAAA | I1: aaaaaaa | J1: aaaaaa | L1: aaaaaaaaa | N1: aaaaaaa | O1: AAAAAA
H2: Dados Basicos do Projeto | L2: Teste do Modo de Operação | P2: Cálculo do Fio Mínimo Bobina
B3: Tap Trafo | C3: Trafo Antigo | H3: Parametro | I3: Valor | J3: Unidade | L3: Parametro | M3: Valor | N3: Unidade | P3: Parametro | Q3: Valor | R3: Unidade
B4: 1º | C4: 0.446 | D4: mH | H4: V in(max) | I4: =Dados_Projeto!D4 -> 12 | J4: V | L4: N1/N2 | M4: =Dados_Projeto!D11 -> 4.5 | P4: Profundidade de Penetração | Q4: =6.62/SQRT(I16) -> 0.02648 | R4: cm
C5: =C4*1000 -> 446 | D5: uH | H5: V in rms | I5: =I4 -> 12 | J5: V | L5: N1/N2 | M5: =Dados_Projeto!D12 -> 5.6 | N5: =(I7/I4)*((1-I11)/I11) -> 0.17857143 | P5: Diametro do Fio | Q5: =2*Q4 -> 0.05296 | R5: cm
B6: 2º | C6: 0.099 | D6: mH | H6: V in(min) | I6: =I4 -> 12 | J6: V | L6: N2/N1 | M6: =1/M4 -> 0.22222222 | P6: Área do Fio (Aw) | Q6: =ROUND((PI()*Q5^2)/4,5) -> 0.0022 | R6: cm²
C7: =C6*1000 -> 99 | D7: uH | H7: V out (1) | I7: =Dados_Projeto!D7 -> 5 | J7: V | L7: N2/N1 | M7: =1/M5 -> 0.17857143 | N7: =1/N5 -> 5.6 | P7: Fio Mínimo Escolhido
B8: N1/N2 | C8: =C5/C7 -> 4.5050505 | H8: R out (1) | I8: 100 | J8: Ω | L8: D (Max Real) | M8: =ROUND(1/(((I5/I7)*(M7)+1)),3) -> 0.7 | P8: Área do Fio (AWG) Mínimo | Q8: =INDEX(AWG!O:O,MATCH("Sim",AWG!Q:Q,0)) -> 0.00205 | R8: cm²
B9: N2/N1 | C9: =C7/C5 -> 0.22197309 | H9: I out (1) | I9: =ROUND(I7/I8,2) -> 0.05 | J9: A | L9: N1/N2 | M9: =1/M6 -> 4.5 | N9: - | P9: Fio AWG | Q9: =INDEX(AWG!B:B,MATCH("Sim",AWG!Q:Q,0)) -> 24 | R9: AWG
H10: P out (1) | I10: =ROUND((I7)*I9,2) -> 0.25 | J10: W | L10: I Lm | M10: =ROUND((I7^2)/(I5*M8*I8),2) -> 0.03 | N10: A | P10: Resistência | Q10: =INDEX(AWG!E:E,MATCH("Sim",AWG!Q:Q,0)) -> 842.1 | R10: uΩ/cm 22º C
H11: Duty Cicle | I11: =Dados_Projeto!D28 -> 0.7 | L11: Qual Duty Cicle | M11: Original | P11: Fio AWG Escolhido | Q11: =INDEX(Anal_Tubes!B:B,MATCH("Sim",Anal_Tubes!P:P,0)) -> 24 | R11: AWG
H12: L Trafo Requerido | I12: =Dados_Projeto!D9 -> 450 | J12: uH | L12: ∆ I Lm | M12: =IF(M11="Calculado",(I4*I11)/(I13*I16),(I4*M8)/(I13*I16)) -> 0.29866667 | N12: A | P12: Área do Fio (AWG) Mínimo | Q12: =_xlfn.XLOOKUP(Q11,AWG!B6:B40,AWG!O6:O40,"",0,1) -> 0.00205 | R12: cm²
H13: L Trafo Requerido | I13: =I12/1000000 -> 0.00045 | J13: H | L13: Lm | M13: =(I5*M8)/(I16*M12) -> 0.00045 | N13: H | P13: Resistência | Q13: =_xlfn.XLOOKUP(Q11,AWG!B6:B40,AWG!E6:E40,"",0,1) -> 842.1 | R13: uΩ/cm 22º C
H14: ∆ Vo | I14: 2 | J14: % | L14: Lm | M14: =ROUND(M13*1000000,1) -> 450 | N14: uH
H15: Frequência | I15: =Dados_Projeto!D14 -> 62.5 | J15: kH | L15: I Lm mín | M15: =M10-(M12/2) -> -0.11933333 | N15: A | P15: Imax | Q15: =M17 -> 0.17933333 | R15: A
H16: Frequência | I16: =I15*1000 -> 62500 | J16: H | P16: Imax 1% | Q16: =Q15*1% -> 0.0017933333 | R16: A
H17: Tipo da Condução | I17: =Dados_Projeto!D30 -> Contínuo | L17: I Lm máx | M17: =M10+(M12/2) -> 0.17933333 | N17: A | P17: Imax 1% | Q17: =ROUND(Q16*1000,2) -> 1.79 | R17: mA
H18: Tipo do Transformador | I18: =Dados_Projeto!D31 -> Toroidal | L18: Modo de Operação Segundo Hart | P18: R snubber | Q18: =ROUND(I4/Q16,0) -> 6691 | R18: Ω | T18: =(100*(10^-6)*(8*10^-3)^2)/2 -> 3.2e-09
H19: Calculos Periodo | L19: =IF(M15<0,"Descontínuo","Contínuo") -> Descontínuo | P19: R snubber cmc | Q19: =INDEX(Resistores_Comerciais!A:A,MATCH("Sim",Resistores_Comerciais!P:P,0)) -> 6800 | R19: Ω | T19: =T18*1000000000 -> 3.2 | U19: nJ
H20: Periodo T | I20: =1/I16 -> 1.6e-05 | J20: s | L20: Definindo o Núcleo | P20: R snubber cmc | Q20: =Q19/1000 -> 6.8 | R20: kΩ
H21: Ton | I21: =I11*I20 -> 1.12e-05 | J21: s | L21: Al do Núcleo | M21: 93 | N21: nH/Np² | P21: Ei | Q21: =(I13*(Q16)^2)/2 -> 7.2361e-10 | R21: J | T21: =T19*2 -> 6.4
I22: 100 | L22: Lm | M22: =M14*1000 -> 450000 | N22: nH | P22: Ei | Q22: =Q21*10^9 -> 0.72361 | R22: nJ
L23: Número de Voltas Primário | M23: =ROUNDDOWN(SQRT(M22/M21),0) -> 69 | N23: Voltas | P23: V teste | Q23: 2 | R23: V
L24: Qntd Fios Primario | M24: =INDEX(Anal_Tubes!Q:Q,MATCH("Sim",Anal_Tubes!P:P,0)) -> 1 | N24: Fios | P24: c snb | Q24: =(Q21*2)/Q23^2 -> 3.61805e-10 | R24: J
L25: Número de Voltas Secundário | M25: =M23*M6 -> 15.333333 | N25: Voltas | P25: c snb | Q25: =Q24*10^6 -> 0.000361805 | R25: uF
L26: Qntd Fios Secundário | M26: 1 | N26: Fios | P26: c snb cmc | Q26: =INDEX(Capacitores_Comerciais!C:C,MATCH("Sim",Capacitores_Comerciais!G:G,0)) -> 4.7e-10 | R26: F
L27: Qual Fio | M27: =Q11 -> 24 | N27: AWG | P27: c snb cmc | Q27: =Q26*10^12 -> 470 | R27: pF | S27: =Q27/1000 -> 0.47
L28: Número de Voltas Secundário | M28: =ROUND(M23*M7,2) -> 12.32 | N28: Voltas | P28: C carga | Q28: =(I7*I11)/((I14%)*I8*I16) -> 2.8e-05 | R28: =12/1000 -> 0.012
L29: Qntd Fios Secundário | M29: 1 | N29: Fios | P29: C Carga cmc | Q29: =INDEX(Capacitores_Comerciais!C:C,MATCH("Sim",Capacitores_Comerciais!E:E,0)) -> 3.3e-05 | R29: F
L30: Qual Fio | M30: =Q14 -> 0 | N30: AWG | P30: C Carga cmc | Q30: =Q29*10^6 -> 33 | R30: uF | T30: 3300 | U30: =T30*1 -> 3300
L31: Modo de Operação Segundo Hart
L32: =IF(M26<0,"Descontínuo","Contínuo") -> Contínuo
L34: =((((1-I11)^2)*I22)/(2*I16))*(M5^2) -> 0.00225792 | M34: lm
L35: =L34*10^6 -> 2257.92 | M35: uLm
L36: =I4*I11*SQRT((I22)/(2*I13*I16)) -> 11.2

Sheet Planilha1
J3: Item | K3: Valor aproximado (R$)
J4: Microcontrolador | K4: XX,00
J5: MOSFET de potência | K5: XX,00
J6: Núcleo toroidal | K6: XX,00
J7: Componentes passivos | K7: XX,00
J8: Custo total estimado | K8: XX,00

Sheet Estudo_OptoAcoplador
C3: OPTOACOPLADOR 4N25
C5: Circuito | D5: Parametro | E5: Valor | F5: Unidade | H5: Parametro | I5: Valor | J5: Unidade
C6: Circ. Teste Datasheet Vin | D6: IC | E6: =Dados_Projeto!D17 -> 1 | F6: mA | H6: Ton | I6: 2 | J6: us
D7: IC | E7: =E6/1000 -> 0.001 | F7: A | I7: =I6/1000000 -> 2e-06 | J7: s
D8: Vcc | E8: 10 | F8: V | H8: Toff | I8: 2 | J8: us
D9: RL | E9: 100 | F9: Ohm | I9: =I8/1000000 -> 2e-06 | J9: s
D10: CTR | E10: 20 | F10: % | H10: T Total | I10: =I8+I6 -> 4 | J10: us
D11: IF | E11: =E6/E10% -> 5 | F11: mA
D12: I coletor | E12: =E10%*E7 -> 0.0002 | F12: A | I12: =I9+I7 -> 4e-06 | J12: s
D13: I coletor | E13: =E12*1000 -> 0.2 | F13: mA | H13: F máx 0,10 mA | I13: =1/I10 -> 0.25 | J13: MH
D14: Queda T Vrl | E14: =E12*E9 -> 0.02 | F14: V | I14: =I13*1000 -> 250 | J14: kH
D15: Vce Final | E15: =E8-E14 -> 9.98 | F15: V | I15: =I13*1000000 -> 250000 | J15: H
D16: V F Led Emissor Tip | E16: 1.18 | F16: V
D17: V F Led Emissor Max | E17: 1.5 | F17: V
C19: Circ. Micro Controlador | D19: Vcc/Vin MicroContr | E19: =Dados_Projeto!D3 -> 5 | F19: V
D20: V F Led | E20: 1.18 | F20: V
D21: I base Led | E21: =E11 -> 5 | F21: mA
D22: I base Led | E22: =E21/1000 -> 0.005 | F22: A
D23: ResistenciaRg | E23: =(E19-E20)/E22 -> 764 | F23: Ohm
D24: Resistencia Comerc. | E24: =INDEX(Resistores_Comerciais!A:A,MATCH("Sim",Resistores_Comerciais!M:M,0)) -> 18000 | F24: Ohm | G24: Menor
D25: I Base Led New | E25: =(E19-E20)/E24 -> 0.00021222222 | F25: A
D26: I Base Led New | E26: =E25*1000 -> 0.21222222 | F26: mA
D27: Diferença I base | E27: =((E25/E22)-1)*100 -> -95.755556 | F27: %

Sheet Controle_Malha_Aberta
H1: J1 | I1: b0 | J1: 36
A2: Passo (k) | B2: Tempo (t) | C2: Entrada u[k] | D2: x[k-2] | E2: x[k-1] | F2: Estado x[k] | G2: Saída y[k] | H2: J2 | I2: b1 | J2: -0.0013499 | K2: =(-1*J1)/26667 -> -0.0013499831
A3: 0 | B3: =0-J6 -> -2e-06 | C3: 0 | D3: 0 | E3: 0 | F3: 0 | G3: 0 | H3: J3 | I3: a0 | J3: 1
A4: 1 | B4: =B3+$J$6 -> 0 | C4: =IF(B4>=0,1,0) -> 1 | D4: =E3 -> 0 | E4: =F3 -> 0 | F4: =(C4 + E4*((2*$J$5)/($J$6^2) + $J$4/$J$6) - D4*($J$5/($J$6^2))) / (($J$5/($J$6^2)) + ($J$4/$J$6) + $J$3) -> 8.0516724e-05 | G4: =$J$2*((F4-E4)/$J$6)+$J$1*F4 -> -0.051446161 | H4: J4 | I4: a1 | J4: 3.756e-05 | K4: =1/26625 -> 3.7558685e-05
A5: 2 | B5: =B4+$J$6 -> 2e-06 | C5: =IF(B5>=0,1,0) -> 1 | D5: =E4 -> 0 | E5: =F4 -> 8.0516724e-05 | F5: =(C5 + E5*((2*$J$4)/($J$5^2) + $J$3/$J$5) - D5*($J$4/($J$5^2))) / (($J$4/($J$5^2)) + ($J$3/$J$5) + $J$2) -> 0.00016092733 | G5: =$J$2*((F5-E5)/$J$6)+$J$1*F5 -> -0.048479753 | H5: J5 | I5: a2 | J5: 4.96e-08 | K5: =1/20160000 -> 4.9603175e-08
A6: 3 | B6: =B5+$J$6 -> 4e-06 | C6: =IF(B6>=0,1,0) -> 1 | D6: =E5 -> 8.0516724e-05 | E6: =F5 -> 0.00016092733 | F6: =(C6 + E6*((2*$J$4)/($J$5^2) + $J$3/$J$5) - D6*($J$4/($J$5^2))) / (($J$4/($J$5^2)) + ($J$3/$J$5) + $J$2) -> 0.00024123195 | G6: =$J$2*((F6-E6)/$J$6)+$J$1*F6 -> -0.045517254 | H6: J6 | I6: Δt (s) | J6: 2e-06 | K6: Passo de tempo, crucial!
A7: 4 | B7: =B6+$J$6 -> 6e-06 | C7: =IF(B7>=0,1,0) -> 1 | D7: =E6 -> 0.00016092733 | E7: =F6 -> 0.00024123195 | F7: =(C7 + E7*((2*$J$4)/($J$5^2) + $J$3/$J$5) - D7*($J$4/($J$5^2))) / (($J$4/($J$5^2)) + ($J$3/$J$5) + $J$2) -> 0.00032143073 | G7: =$J$2*((F7-E7)/$J$6)+$J$1*F7 -> -0.042558661
A8: 5 | B8: =B7+$J$6 -> 8e-06 | C8: =IF(B8>=0,1,0) -> 1 | D8: =E7 -> 0.00024123195 | E8: =F7 -> 0.00032143073 | F8: =(C8 + E8*((2*$J$4)/($J$5^2) + $J$3/$J$5) - D8*($J$4/($J$5^2))) / (($J$4/($J$5^2)) + ($J$3/$J$5) + $J$2) -> 0.00040152381 | G8: =$J$2*((F8-E8)/$J$6)+$J$1*F8 -> -0.039603967
A9: 6 | B9: =B8+$J$6 -> 1e-05 | C9: =IF(B9>=0,1,0) -> 1 | D9: =E8 -> 0.00032143073 | E9: =F8 -> 0.00040152381 | F9: =(C9 + E9*((2*$J$4)/($J$5^2) + $J$3/$J$5) - D9*($J$4/($J$5^2))) / (($J$4/($J$5^2)) + ($J$3/$J$5) + $J$2) -> 0.00048151133 | G9: =$J$2*((F9-E9)/$J$6)+$J$1*F9 -> -0.036653167
A10: 7 | B10: =B9+$J$6 -> 1.2e-05 | C10: =IF(B10>=0,1,0) -> 1 | D10: =E9 -> 0.00040152381 | E10: =F9 -> 0.00048151133 | F10: =(C10 + E10*((2*$J$4)/($J$5^2) + $J$3/$J$5) - D10*($J$4/($J$5^2))) / (($J$4/($J$5^2)) + ($J$3/$J$5) + $J$2) -> 0.00056139342 | G10: =$J$2*((F10-E10)/$J$6)+$J$1*F10 -> -0.033706256
A11: 8 | B11: =B10+$J$6 -> 1.4e-05 | C11: =IF(B11>=0,1,0) -> 1 | D11: =E10 -> 0.00048151133 | E11: =F10 -> 0.00056139342 | F11: =(C11 + E11*((2*$J$4)/($J$5^2) + $J$3/$J$5) - D11*($J$4/($J$5^2))) / (($J$4/($J$5^2)) + ($J$3/$J$5) + $J$2) -> 0.00064117023 | G11: =$J$2*((F11-E11)/$J$6)+$J$1*F11 -> -0.030763229
A12: 9 | B12: =B11+$J$6 -> 1.6e-05 | C12: =IF(B12>=0,1,0) -> 1 | D12: =E11 -> 0.00056139342 | E12: =F11 -> 0.00064117023 | F12: =(C12 + E12*((2*$J$4)/($J$5^2) + $J$3/$J$5) - D12*($J$4/($J$5^2))) / (($J$4/($J$5^2)) + ($J$3/$J$5) + $J$2) -> 0.00072084189 | G12: =$J$2*((F12-E12)/$J$6)+$J$1*F12 -> -0.027824082
A13: 10 | B13: =B12+$J$6 -> 1.8e-05 | C13: =IF(B13>=0,1,0) -> 1 | D13: =E12 -> 0.00064117023 | E13: =F12 -> 0.00072084189 | F13: =(C13 + E13*((2*$J$4)/($J$5^2) + $J$3/$J$5) - D13*($J$4/($J$5^2))) / (($J$4/($J$5^2)) + ($J$3/$J$5) + $J$2) -> 0.00080040855 | G13: =$J$2*((F13-E13)/$J$6)+$J$1*F13 -> -0.024888808
A14: 11 | B14: =B13+$J$6 -> 2e-05 | C14: =IF(B14>=0,1,0) -> 1 | D14: =E13 -> 0.00072084189 | E14: =F13 -> 0.00080040855 | F14: =(C14 + E14*((2*$J$4)/($J$5^2) + $J$3/$J$5) - D14*($J$4/($J$5^2))) / (($J$4/($J$5^2)) + ($J$3/$J$5) + $J$2) -> 0.00087987034 | G14: =$J$2*((F14-E14)/$J$6)+$J$1*F14 -> -0.021957403
A15: 12 | B15: =B14+$J$6 -> 2.2e-05 | C15: =IF(B15>=0,1,0) -> 1 | D15: =E14 -> 0.00080040855 | E15: =F14 -> 0.00087987034 | F15: =(C15 + E15*((2*$J$4)/($J$5^2) + $J$3/$J$5) - D15*($J$4/($J$5^2))) / (($J$4/($J$5^2)) + ($J$3/$J$5) + $J$2) -> 0.0009592274 | G15: =$J$2*((F15-E15)/$J$6)+$J$1*F15 -> -0.019029861
A16: 13 | B16: =B15+$J$6 -> 2.4e-05 | C16: =IF(B16>=0,1,0) -> 1 | D16: =E15 -> 0.00087987034 | E16: =F15 -> 0.0009592274 | F16: =(C16 + E16*((2*$J$4)/($J$5^2) + $J$3/$J$5) - D16*($J$4/($J$5^2))) / (($J$4/($J$5^2)) + ($J$3/$J$5) + $J$2) -> 0.0010384799 | G16: =$J$2*((F16-E16)/$J$6)+$J$1*F16 -> -0.016106178
A17: 14 | B17: =B16+$J$6 -> 2.6e-05 | C17: =IF(B17>=0,1,0) -> 1 | D17: =E16 -> 0.0009592274 | E17: =F16 -> 0.0010384799 | F17: =(C17 + E17*((2*$J$4)/($J$5^2) + $J$3/$J$5) - D17*($J$4/($J$5^2))) / (($J$4/($J$5^2)) + ($J$3/$J$5) + $J$2) -> 0.0011176279 | G17: =$J$2*((F17-E17)/$J$6)+$J$1*F17 -> -0.013186349
A18: 15 | B18: =B17+$J$6 -> 2.8e-05 | C18: =IF(B18>=0,1,0) -> 1 | D18: =E17 -> 0.0010384799 | E18: =F17 -> 0.0011176279 | F18: =(C18 + E18*((2*$J$4)/($J$5^2) + $J$3/$J$5) - D18*($J$4/($J$5^2))) / (($J$4/($J$5^2)) + ($J$3/$J$5) + $J$2) -> 0.0011966716 | G18: =$J$2*((F18-E18)/$J$6)+$J$1*F18 -> -0.010270367
... A26: 23 | B26: =B25+$J$6 -> 4.4e-05 | C26: =IF(B26>=0,1,0) -> 1 | D26: =E25 -> 0.0016687508 | E26: =F25 -> 0.0017470682 | F26: =(C26 + E26*((2*$J$4)/($J$5^2) + $J$3/$J$5) - D26*($J$4/($J$5^2))) / (($J$4/($J$5^2)) + ($J$3/$J$5) + $J$2) -> 0.0018252823 | G26: =$J$2*((F26-E26)/$J$6)+$J$1*F26 -> 0.012919549

Sheet Anal_Tubes
B2: Numero | C2: Diâmetro | D2: Espiras | E2: Área | F2: Resistência | G2: Peso | H2: Comprim. | I2: Corrente máxima (A) | L2: Frequência | M2: Corrente_Max | N2: Frequencia | O2: 5 % HZ | P2: Teste_HZ | Q2: Qntd_Fios | R2: Corrente_2 | S2: Qntd_Fios_2
B3: AWG | C3: (mm) | D3: por cm | E3: (mm2) | F3: (Ω/km) | G3: (kg/km) | H3: (m/kg) | I3: 2,5A/mm2 | J3: 3A/mm2 | K3: 6A/mm2 | L3: máx. (kHz) | M3: A | N3: Hz | O3: Hz | P3: - | Q3: Numero | S3: Numero
B4: 1 | C4: 7.3482 | D4: 1.361 | E4: 42.409 | F4: 0.406 | G4: 380 | H4: 2.6317 | I4: 106.022 | J4: 127.226 | K4: 254.453 | L4: 0.323 | M4: =Calculo_FlyBack_Simples!$M$17 -> 0.17933333 | N4: =Calculo_FlyBack_Simples!$I$15 -> 62.5 | O4: =N4*0.95 -> 59.375 | P4: =IF(L4>O4,"Sim","Não") -> Não | Q4: =IF(AND(P4="Sim",P3="Não"), IF(M4<=2.5,IF(ROUND(M4/I4,0)=0,1,ROUND(M4/I4,0)), IF(M4<=3,IF(ROUND(M4/J4,0)=0,1,ROUND(M4/J4,0)), IF(ROUND(M4/K4,0)=0,1,ROUND(M4/K4,0)))),"") | R4: =Calculo_FlyBack_Simples!$I$9 -> 0.05 | S4: =IF(AND(P4="Sir",P3="Não"), IF(R4<=2.5,IF(ROUND(R4/I4,0)=0,1,ROUND(R4/I4,0)), IF(R4<=3,IF(ROUND(R4/J4,0)=0,1,ROUND(R4/J4,0)), IF(ROUND(R4/K4,0)=0,1,ROUND(R4/K4,0)))),"")
B5: 2 | C5: 6.5438 | D5: 1.528 | E5: 33.632 | F5: 0.511 | G5: 301.3 | H5: 3.3185 | I5: 84.08 | J5: 100.896 | K5: 201.792 | L5: 0.407 | M5: =Calculo_FlyBack_Simples!$M$17 -> 0.17933333 | N5: =Calculo_FlyBack_Simples!$I$15 -> 62.5 | O5: =N5*0.95 -> 59.375 | P5: =IF(L5>O5,"Sim","Não") -> Não | Q5: =IF(AND(P5="Sim",P4="Não"), IF(M5<=2.5,IF(ROUND(M5/I5,0)=0,1,ROUND(M5/I5,0)), IF(M5<=3,IF(ROUND(M5/J5,0)=0,1,ROUND(M5/J5,0)), IF(ROUND(M5/K5,0)=0,1,ROUND(M5/K5,0)))),"") | R5: =Calculo_FlyBack_Simples!$I$9 -> 0.05 | S5: =IF(AND(P5="Sir",P4="Não"), IF(R5<=2.5,IF(ROUND(R5/I5,0)=0,1,ROUND(R5/I5,0)), IF(R5<=3,IF(ROUND(R5/J5,0)=0,1,ROUND(R5/J5,0)), IF(ROUND(R5/K5,0)=0,1,ROUND(R5/K5,0)))),"")
B6: 3 | C6: 5.8275 | D6: 1.716 | E6: 26.671 | F6: 0.645 | G6: 239 | H6: 4.1845 | I6: 66.679 | J6: 80.014 | K6: 160.029 | L6: 0.513 | M6: =Calculo_FlyBack_Simples!$M$17 -> 0.17933333 | N6: =Calculo_FlyBack_Simples!$I$15 -> 62.5 | O6: =N6*0.95 -> 59.375 | P6: =IF(L6>O6,"Sim","Não") -> Não | Q6: =IF(AND(P6="Sim",P5="Não"), IF(M6<=2.5,IF(ROUND(M6/I6,0)=0,1,ROUND(M6/I6,0)), IF(M6<=3,IF(ROUND(M6/J6,0)=0,1,ROUND(M6/J6,0)), IF(ROUND(M6/K6,0)=0,1,ROUND(M6/K6,0)))),"") | R6: =Calculo_FlyBack_Simples!$I$9 -> 0.05 | S6: =IF(AND(P6="Sir",P5="Não"), IF(R6<=2.5,IF(ROUND(R6/I6,0)=0,1,ROUND(R6/I6,0)), IF(R6<=3,IF(ROUND(R6/J6,0)=0,1,ROUND(R6/J6,0)), IF(ROUND(R6/K6,0)=0,1,ROUND(R6/K6,0)))),"")
B7: 4 | C7: 5.1895 | D7: 1.927 | E7: 21.152 | F7: 0.813 | G7: 189.5 | H7: 5.2765 | I7: 52.879 | J7: 63.455 | K7: 126.91 | L7: 0.647 | M7: =Calculo_FlyBack_Simples!$M$17 -> 0.17933333 | N7: =Calculo_FlyBack_Simples!$I$15 -> 62.5 | O7: =N7*0.95 -> 59.375 | P7: =IF(L7>O7,"Sim","Não") -> Não | Q7: =IF(AND(P7="Sim",P6="Não"), IF(M7<=2.5,IF(ROUND(M7/I7,0)=0,1,ROUND(M7/I7,0)), IF(M7<=3,IF(ROUND(M7/J7,0)=0,1,ROUND(M7/J7,0)), IF(ROUND(M7/K7,0)=0,1,ROUND(M7/K7,0)))),"") | R7: =Calculo_FlyBack_Simples!$I$9 -> 0.05 | S7: =IF(AND(P7="Sir",P6="Não"), IF(R7<=2.5,IF(ROUND(R7/I7,0)=0,1,ROUND(R7/I7,0)), IF(R7<=3,IF(ROUND(R7/J7,0)=0,1,ROUND(R7/J7,0)), IF(ROUND(R7/K7,0)=0,1,ROUND(R7/K7,0)))),"")
B8: 5 | C8: 4.6214 | D8: 2.164 | E8: 16.774 | F8: 1.025 | G8: 150.3 | H8: 6.6535 | I8: 41.935 | J8: 50.322 | K8: 100.645 | L8: 0.816 | M8: =Calculo_FlyBack_Simples!$M$17 -> 0.17933333 | N8: =Calculo_FlyBack_Simples!$I$15 -> 62.5 | O8: =N8*0.95 -> 59.375 | P8: =IF(L8>O8,"Sim","Não") -> Não | Q8: =IF(AND(P8="Sim",P7="Não"), IF(M8<=2.5,IF(ROUND(M8/I8,0)=0,1,ROUND(M8/I8,0)), IF(M8<=3,IF(ROUND(M8/J8,0)=0,1,ROUND(M8/J8,0)), IF(ROUND(M8/K8,0)=0,1,ROUND(M8/K8,0)))),"") | R8: =Calculo_FlyBack_Simples!$I$9 -> 0.05 | S8: =IF(AND(P8="Sir",P7="Não"), IF(R8<=2.5,IF(ROUND(R8/I8,0)=0,1,ROUND(R8/I8,0)), IF(R8<=3,IF(ROUND(R8/J8,0)=0,1,ROUND(R8/J8,0)), IF(ROUND(R8/K8,0)=0,1,ROUND(R8/K8,0)))),"")
B9: 6 | C9: 4.1155 | D9: 2.43 | E9: 13.303 | F9: 1.293 | G9: 119.2 | H9: 8.3899 | I9: 33.256 | J9: 39.908 | K9: 79.815 | L9: 1.029 | M9: =Calculo_FlyBack_Simples!$M$17 -> 0.17933333 | N9: =Calculo_FlyBack_Simples!$I$15 -> 62.5 | O9: =N9*0.95 -> 59.375 | P9: =IF(L9>O9,"Sim","Não") -> Não | Q9: =IF(AND(P9="Sim",P8="Não"), IF(M9<=2.5,IF(ROUND(M9/I9,0)=0,1,ROUND(M9/I9,0)), IF(M9<=3,IF(ROUND(M9/J9,0)=0,1,ROUND(M9/J9,0)), IF(ROUND(M9/K9,0)=0,1,ROUND(M9/K9,0)))),"") | R9: =Calculo_FlyBack_Simples!$I$9 -> 0.05 | S9: =IF(AND(P9="Sir",P8="Não"), IF(R9<=2.5,IF(ROUND(R9/I9,0)=0,1,ROUND(R9/I9,0)), IF(R9<=3,IF(ROUND(R9/J9,0)=0,1,ROUND(R9/J9,0)), IF(ROUND(R9/K9,0)=0,1,ROUND(R9/K9,0)))),"")
B10: 7 | C10: 3.665 | D10: 2.729 | E10: 10.549 | F10: 1.63 | G10: 94.52 | H10: 10.579 | I10: 26.374 | J10: 31.648 | K10: 63.297 | L10: 1.297 | M10: =Calculo_FlyBack_Simples!$M$17 -> 0.17933333 | N10: =Calculo_FlyBack_Simples!$I$15 -> 62.5 | O10: =N10*0.95 -> 59.375 | P10: =IF(L10>O10,"Sim","Não") -> Não | Q10: =IF(AND(P10="Sim",P9="Não"), IF(M10<=2.5,IF(ROUND(M10/I10,0)=0,1,ROUND(M10/I10,0)), IF(M10<=3,IF(ROUND(M10/J10,0)=0,1,ROUND(M10/J10,0)), IF(ROUND(M10/K10,0)=0,1,ROUND(M10/K10,0)))),"") | R10: =Calculo_FlyBack_Simples!$I$9 -> 0.05 | S10: =IF(AND(P10="Sir",P9="Não"), IF(R10<=2.5,IF(ROUND(R10/I10,0)=0,1,ROUND(R10/I10,0)), IF(R10<=3,IF(ROUND(R10/J10,0)=0,1,ROUND(R10/J10,0)), IF(ROUND(R10/K10,0)=0,1,ROUND(R10/K10,0)))),"")
B11: 8 | C11: 3.2638 | D11: 3.064 | E11: 8.366 | F11: 2.056 | G11: 74.96 | H11: 13.34 | I11: 20.915 | J11: 25.098 | K11: 50.197 | L11: 1.636 | M11: =Calculo_FlyBack_Simples!$M$17 -> 0.17933333 | N11: =Calculo_FlyBack_Simples!$I$15 -> 62.5 | O11: =N11*0.95 -> 59.375 | P11: =IF(L11>O11,"Sim","Não") -> Não | Q11: =IF(AND(P11="Sim",P10="Não"), IF(M11<=2.5,IF(ROUND(M11/I11,0)=0,1,ROUND(M11/I11,0)), IF(M11<=3,IF(ROUND(M11/J11,0)=0,1,ROUND(M11/J11,0)), IF(ROUND(M11/K11,0)=0,1,ROUND(M11/K11,0)))),"") | R11: =Calculo_FlyBack_Simples!$I$9 -> 0.05 | S11: =IF(AND(P11="Sir",P10="Não"), IF(R11<=2.5,IF(ROUND(R11/I11,0)=0,1,ROUND(R11/I11,0)), IF(R11<=3,IF(ROUND(R11/J11,0)=0,1,ROUND(R11/J11,0)), IF(ROUND(R11/K11,0)=0,1,ROUND(R11/K11,0)))),"")
B12: 9 | C12: 2.9065 | D12: 3.441 | E12: 6.635 | F12: 2.592 | G12: 59.45 | H12: 16.822 | I12: 16.587 | J12: 19.904 | K12: 39.808 | L12: 2.063 | M12: =Calculo_FlyBack_Simples!$M$17 -> 0.17933333 | N12: =Calculo_FlyBack_Simples!$I$15 -> 62.5 | O12: =N12*0.95 -> 59.375 | P12: =IF(L12>O12,"Sim","Não") -> Não | Q12: =IF(AND(P12="Sim",P11="Não"), IF(M12<=2.5,IF(ROUND(M12/I12,0)=0,1,ROUND(M12/I12,0)), IF(M12<=3,IF(ROUND(M12/J12,0)=0,1,ROUND(M12/J12,0)), IF(ROUND(M12/K12,0)=0,1,ROUND(M12/K12,0)))),"") | R12: =Calculo_FlyBack_Simples!$I$9 -> 0.05 | S12: =IF(AND(P12="Sir",P11="Não"), IF(R12<=2.5,IF(ROUND(R12/I12,0)=0,1,ROUND(R12/I12,0)), IF(R12<=3,IF(ROUND(R12/J12,0)=0,1,ROUND(R12/J12,0)), IF(ROUND(R12/K12,0)=0,1,ROUND(R12/K12,0)))),"")
B13: 10 | C13: 2.5883 | D13: 3.864 | E13: 5.262 | F13: 3.269 | G13: 47.14 | H13: 21.212 | I13: 13.154 | J13: 15.785 | K13: 31.57 | L13: 2.601 | M13: =Calculo_FlyBack_Simples!$M$17 -> 0.17933333 | N13: =Calculo_FlyBack_Simples!$I$15 -> 62.5 | O13: =N13*0.95 -> 59.375 | P13: =IF(L13>O13,"Sim","Não") -> Não | Q13: =IF(AND(P13="Sim",P12="Não"), IF(M13<=2.5,IF(ROUND(M13/I13,0)=0,1,ROUND(M13/I13,0)), IF(M13<=3,IF(ROUND(M13/J13,0)=0,1,ROUND(M13/J13,0)), IF(ROUND(M13/K13,0)=0,1,ROUND(M13/K13,0)))),"") | R13: =Calculo_FlyBack_Simples!$I$9 -> 0.05 | S13: =IF(AND(P13="Sir",P12="Não"), IF(R13<=2.5,IF(ROUND(R13/I13,0)=0,1,ROUND(R13/I13,0)), IF(R13<=3,IF(ROUND(R13/J13,0)=0,1,ROUND(R13/J13,0)), IF(ROUND(R13/K13,0)=0,1,ROUND(R13/K13,0)))),"")
B14: 11 | C14: 2.305 | D14: 4.338 | E14: 4.173 | F14: 4.122 | G14: 37.39 | H14: 26.747 | I14: 10.432 | J14: 12.518 | K14: 25.036 | L14: 3.28 | M14: =Calculo_FlyBack_Simples!$M$17 -> 0.17933333 | N14: =Calculo_FlyBack_Simples!$I$15 -> 62.5 | O14: =N14*0.95 -> 59.375 | P14: =IF(L14>O14,"Sim","Não") -> Não | Q14: =IF(AND(P14="Sim",P13="Não"), IF(M14<=2.5,IF(ROUND(M14/I14,0)=0,1,ROUND(M14/I14,0)), IF(M14<=3,IF(ROUND(M14/J14,0)=0,1,ROUND(M14/J14,0)), IF(ROUND(M14/K14,0)=0,1,ROUND(M14/K14,0)))),"") | R14: =Calculo_FlyBack_Simples!$I$9 -> 0.05 | S14: =IF(AND(P14="Sir",P13="Não"), IF(R14<=2.5,IF(ROUND(R14/I14,0)=0,1,ROUND(R14/I14,0)), IF(R14<=3,IF(ROUND(R14/J14,0)=0,1,ROUND(R14/J14,0)), IF(ROUND(R14/K14,0)=0,1,ROUND(R14/K14,0)))),"")
B15: 12 | C15: 2.0526 | D15: 4.872 | E15: 3.309 | F15: 5.198 | G15: 29.65 | H15: 33.727 | I15: 8.273 | J15: 9.927 | K15: 19.855 | L15: 4.136 | M15: =Calculo_FlyBack_Simples!$M$17 -> 0.17933333 | N15: =Calculo_FlyBack_Simples!$I$15 -> 62.5 | O15: =N15*0.95 -> 59.375 | P15: =IF(L15>O15,"Sim","Não") -> Não | Q15: =IF(AND(P15="Sim",P14="Não"), IF(M15<=2.5,IF(ROUND(M15/I15,0)=0,1,ROUND(M15/I15,0)), IF(M15<=3,IF(ROUND(M15/J15,0)=0,1,ROUND(M15/J15,0)), IF(ROUND(M15/K15,0)=0,1,ROUND(M15/K15,0)))),"") | R15: =Calculo_FlyBack_Simples!$I$9 -> 0.05 | S15: =IF(AND(P15="Sir",P14="Não"), IF(R15<=2.5,IF(ROUND(R15/I15,0)=0,1,ROUND(R15/I15,0)), IF(R15<=3,IF(ROUND(R15/J15,0)=0,1,ROUND(R15/J15,0)), IF(ROUND(R15/K15,0)=0,1,ROUND(R15/K15,0)))),"")
... B47: 44 | C47: 0.05024 | D47: 199.048 | E47: 0.00198 | F47: 8676.677 | G47: 0.01776 | H47: 56301.1 | I47: 0.00496 | J47: 0.00595 | K47: 0.0119 | L47: 6904.681 | M47: =Calculo_FlyBack_Simples!$M$17 -> 0.17933333 | N47: =Calculo_FlyBack_Simples!$I$15 -> 62.5 | O47: =N47*0.95 -> 59.375 | P47: =IF(L47>O47,"Sim","Não") -> Sim | Q47: =IF(AND(P47="Sim",P46="Não"), IF(M47<=2.5,IF(ROUND(M47/I47,0)=0,1,ROUND(M47/I47,0)), IF(M47<=3,IF(ROUND(M47/J47,0)=0,1,ROUND(M47/J47,0)), IF(ROUND(M47/K47,0)=0,1,ROUND(M47/K47,0)))),"") | R47: =Calculo_FlyBack_Simples!$I$9 -> 0.05 | S47: =IF(AND(P47="Sir",P46="Não"), IF(R47<=2.5,IF(ROUND(R47/I47,0)=0,1,ROUND(R47/I47,0)), IF(R47<=3,IF(ROUND(R47/J47,0)=0,1,ROUND(R47/J47,0)), IF(ROUND(R47/K47,0)=0,1,ROUND(R47/K47,0)))),"")

Sheet Calculo_Flyback
A1: AAAAAA | E1: AAAAAA | F1: aaaaaaaaa | G1: aaaaaa | H1: aaaaaaa | I1: AAAAAA | M1: AAAAAA | Q1: AAAAAA | U1: AAAAAA
B2: Dados Basicos do Projeto | F2: Cálculo do Fio Mínimo Bobina | J2: Método Contínuo (MCLYMAN) | N2: Dados da Toroide Utilizada | R2: Calculos do Transformador Secundario 1 (Vout1) | V2: Calculos Gerais do Transformador
B3: Parametro | C3: Valor | D3: Unidade | F3: Parametro | G3: Valor | H3: Unidade | J3: Correntes do Primário | N3: Parametro | O3: Valor | P3: Unidade | R3: Parametro | S3: Valor | T3: Unidade | V3: Parametro | W3: Valor | X3: Unidade
B4: V in(max) | C4: =Dados_Projeto!D4 -> 12 | D4: V | F4: Profundidade de Penetração | G4: =6.62/SQRT(C25) -> 0.041868556 | H4: cm | J4: Parametro | K4: Valor | L4: Unidade | N4: Core Number | O4: T106-26 | R4: Numero de Espiras Secundario 1 Ns1 | S4: =(O33*(C12+C11)*(1-C21-C22))/(C6*C21) -> #REF! | T4: Voltas | V4: Espiras Primario | W4: =O25*O33 -> #REF! | X4: Voltas
B5: V in rms | C5: =Dados_Projeto!D5 -> 12 | D5: V | F5: Diametro do Fio | G5: =2*G4 -> 0.083737112 | H5: cm | J5: D min | K5: =(C6/C4)*C21 -> 0.7 | N5: Fabricante | O5: Magnetics | R5: Numero de Espiras Secundario 1 Ns1 | S5: =ROUND(S4,0) -> #REF! | T5: Voltas | V5: Espiras S1 Secundario | W5: =S5*S10 -> #REF! | X5: Voltas
B6: V in(min) | C6: =Dados_Projeto!D6 -> 12 | D6: V | F6: Área do Fio (Aw) | G6: =ROUND((PI()*G5^2)/4,5) -> 0.00551 | H6: cm² | J6: T off (max) | K6: =C31*(1-K5) -> 1.2e-05 | L6: s | N6: Material | O6: Iron Powder | R6: Corrente de Pico Is1(pk) | S6: =(2*C14)/(1-C21-C22) -> #REF! | T6: A | V6: Espiras S2 Secundario | W6: =S18*S23 -> #REF! | X6: Voltas
B7: R in rms | C7: =ROUND(C5/C8,2) -> 0.05 | D7: Ω | F7: Fio Mínimo Escolhido | J7: Lm rms Calc 1 | K7: =ROUND((((C4*K5)^2)*C31)/(2*C10),9) -> 4.95e-07 | L7: H | N7: MPL | O7: =_xlfn.XLOOKUP(O4,Toroide_Iron_Powder!H:H,Toroide_Iron_Powder!L:L,"",0,1) -> 6.49 | P7: cm | R7: Corrente de RMS Is1(rms) | S7: =ROUND(S6*SQRT((1-C21-C22)/3),2) -> #REF! | T7: A | V7: Total Espiras | W7: =SUM(W4:W6) -> #REF! | X7: Voltas
B8: I in (max) | C8: =ROUND(C20/(C6*C9%),2) -> 237.5 | D8: A | F8: Área do Fio (AWG) Mínimo | G8: =INDEX(AWG!O:O,MATCH("Sim",AWG!Q:Q,0)) -> 0.00205 | H8: cm² | J8: Lm rms Contínuo | K8: =IF(C28="Contínuo",G21,K7) -> 0.00056375839 | L8: H | N8: Core Weight | O8: =_xlfn.XLOOKUP(O4,Toroide_Iron_Powder!H:H,Toroide_Iron_Powder!J:J,"",0,1) -> 29.94 | P8: gramas | R8: Area do Fio Secundario Asw1(b) | S8: =ROUND(S7/O22,5) -> #REF! | T8: cm² | V8: Ku total | W8: =W7*G12/O12 -> #REF! | X8: constante
B9: n eficiência | C9: =Dados_Projeto!D26 -> 1 | D9: % | F9: Fio AWG | G9: =INDEX(AWG!B:B,MATCH("Sim",AWG!Q:Q,0)) -> 24 | H9: AWG | J9: Lm rms | K9: =K8*1000000 -> 563.75839 | L9: uH | N9: Copper Weight Wteu | O9: =_xlfn.XLOOKUP(O4,Toroide_Iron_Powder!H:H,Toroide_Iron_Powder!I:I,"",0,1) -> 23.05 | P9: gramas | R9: Numero de Fios Paralelos Sn S1 | S9: =S8/G12 -> #REF! | T9: fios | V9: Perda Total de Cobre | W9: =S13+S26+O37 -> #REF! | X9: W
B10: P in rms | C10: =ROUND(C20/C9%,2) -> 2850 | D10: W | F10: Resistência | G10: =INDEX(AWG!E:E,MATCH("Sim",AWG!Q:Q,0)) -> 842.1 | H10: uΩ/cm 22º C | J10: ∆ Lm rms | K10: =ROUND((C31*C6*C21)/K8,2) -> 0.6 | L10: A | N10: MLT | O10: =_xlfn.XLOOKUP(O4,Toroide_Iron_Powder!H:H,Toroide_Iron_Powder!K:K,"",0,1) -> 3.93 | P10: cm | R10: Numero de Fios Paralelos Sn S1 | S10: =ROUND(S9,0) -> #REF! | T10: fios | V10: Regulação Alpha | W10: =W9/C20 -> #REF! | X10: %
B11: V diodo | C11: =Dados_Projeto!D27 -> 0.7 | D11: V | F11: Fio AWG Escolhido | G11: =Dados_Projeto!#REF! -> #REF! | H11: AWG | J11: I in (max) | K11: =C8 -> 237.5 | L11: A | N11: Iron Area Ac | O11: =_xlfn.XLOOKUP(O4,Toroide_Iron_Powder!H:H,Toroide_Iron_Powder!O:O,"",0,1) -> 0.659 | P11: cm² | R11: Novo S1 micro Ohm | S11: =ROUND(G13/S10,0) -> #REF! | T11: uΩ/cm 22º C | V11: Densidade de Fluxo Ac, Bac | W11: =(0.4*PI()*O33*O31*(K12/2)*10^-4)/(O29+(O7/O16)) -> #REF! | X11: Testa
B12: V out (1) | C12: 5 | D12: V | F12: Área do Fio (AWG) Mínimo | G12: =_xlfn.XLOOKUP(G11,AWG!B6:B40,AWG!O6:O40,"",0,1) -> #REF! | H12: cm² | J12: I p(pk) primary | K12: =IF(C28="Contínuo",ROUND((C8/C21)+(K10/2),2),K21) -> 339.59 | L12: A | N12: Window Area Wa | O12: =_xlfn.XLOOKUP(O4,Toroide_Iron_Powder!H:H,Toroide_Iron_Powder!P:P,"",0,1) -> 1.65 | P12: cm² | R12: Nova resistencia do Secundario S1 | S12: =O10*S5*S11*10^-6 -> #REF! | T12: Ω | V12: Perda em Watts por Kilograma WK | W12: =ROUND(4.855*(10^-5)*(C25^1.63)*(W11^2.62),1) -> #REF! | X12: Watts/grama
B13: R out (1) | C13: 1 | D13: Ω | F13: Resistência | G13: =_xlfn.XLOOKUP(G11,AWG!B6:B40,AWG!E6:E40,"",0,1) -> #REF! | H13: uΩ/cm 22º C | J13: I p(rms - pk) primary | K13: =IF(C28="Contínuo",ROUND(K12*SQRT((C32/(3*C31))),2),K22) -> 164.04 | L13: A | N13: Area Product Ap | O13: =_xlfn.XLOOKUP(O4,Toroide_Iron_Powder!H:H,Toroide_Iron_Powder!Q:Q,"",0,1) -> 1.08766 | P13: cm⁴ | R13: Perda de Cobre do Secundario S1 | S13: =ROUND((S7^2)*S12,4) -> #REF! | T13: W | V13: Perda no núcleo | W13: =W12*O8*10^-3 -> #REF! | X13: W
B14: I out (1) | C14: =ROUND(C12/C13,2) -> 5 | D14: A | N14: Core Geometry Kg | O14: =_xlfn.XLOOKUP(O4,Toroide_Iron_Powder!H:H,Toroide_Iron_Powder!R:R,"",0,1) -> 0.07299 | P14: cm⁵ | V14: Perda do Núcleo + Cobre | W14: =W13+W9 -> #REF! | X14: W
B15: P out (1) | C15: =ROUND((C11+C12)*C14,2) -> 28.5 | D15: W | F15: Teste do Modo de Operação | J15: Método Descontínuo (MCLYMAN) | N15: Surface Area At | O15: =_xlfn.XLOOKUP(O4,Toroide_Iron_Powder!H:H,Toroide_Iron_Powder!S:S,"",0,1) -> 38 | P15: cm | R15: Calculos do Transformador Secundario 2 (Vout2) | V15: Densidade de Potencia tridente | W15: =W14/O15 -> #REF! | X15: W/cm²
B16: V out (2) | C16: 0 | D16: V | F16: Parametro | G16: Valor | H16: Unidade | J16: Correntes do Primário | N16: Core Permeability | O16: 2500 | R16: Parametro | S16: Valor | T16: Unidade | V16: Elevação de Temperatura | W16: =ROUND(450*(W15^0.826),1) -> #REF! | X16: ºC
B17: R out (2) | C17: 0 | D17: Ω | F17: N2/N1 | G17: =(C12/C5)*((1-C21)/C21) -> 0.17857143 | H17: - | J17: Parametro | K17: Valor | L17: Unidade | N17: Winding Leangth G | O17: 0.62 | P17: cm | R17: Numero de Espiras Secundario 1 Ns1 | S17: =(O33*(C16+C11)*(1-C21-C22))/(C6*C21) -> #REF! | T17: Voltas
B18: I out (2) | C18: =IF(OR(C17=0,C16=0),0,C16/C17) -> 0 | D18: A | F18: N1/N2 | G18: =1/G17 -> 5.6 | H18: - | J18: L p max | K18: =ROUND((C7*C31*C21^2)/2,9) -> 4.9e-07 | L18: H | N18: Al do Núcleo | O18: 93 | P18: nH/Np² | R18: Numero de Espiras Secundario 1 Ns1 | S18: =ROUND(S17,0) -> #REF! | T18: Voltas | V18: Calculos Gerais do Capacitor Out
B19: P out (2) | C19: =(C16+C11)*C18 -> 0 | D19: W | F19: I Lm | G19: =ROUND((C12^2)/(C5*C21*C13),2) -> 2.98 | H19: A | J19: L p max | K19: =K18*1000000 -> 0.49 | L19: uH | R19: Corrente de Pico Is1(pk) | S19: =(2*C18)/(1-C21-C22) -> #REF! | T19: A | V19: Parametro | W19: Valor | X19: Unidade
B20: P out max | C20: =ROUND(C19+C15,1) -> 28.5 | D20: W | F20: ∆ I Lm | G20: =G19*C23% -> 0.596 | H20: A | J20: I in (max) | K20: =C8 -> 237.5 | L20: A | N20: Calculos do Transformador Primario | R20: Corrente de RMS Is1(rms) | S20: =ROUND(S19*SQRT((1-C21-C22)/3),3) -> #REF! | T20: A | V20: I Lm | W20: =G25 -> 0 | X20: A
B21: D (Max) | C21: =Dados_Projeto!D28 -> 0.7 | F21: Lm | G21: =(C5*C21)/(G20*C25) -> 0.00056375839 | H21: H | J21: I p(pk) primary | K21: =ROUND((2*C20*C31)/((C9%)*C6*C32),2) -> 678.57 | L21: A | N21: Parametro | O21: Valor | P21: Unidade | R21: Area do Fio Secundario Asw1(b) | S21: =ROUND(S20/O22,5) -> #REF! | T21: cm² | V21: ∆ I Lm | W21: =ROUND((C5*C21)/(K8*C25),2) -> 0.6 | X21: A
B22: D (well) | C22: =Dados_Projeto!#REF! -> #REF! | F22: Lm | G22: =ROUND(G21*1000000,0) -> 564 | H22: uH | J22: I p(rms - pk) primary | K22: =ROUND(K21*SQRT((C32/(3*C31))),2) -> 327.78 | L22: A | N22: Energia J | O22: =ROUNDUP((2*(K25)*10^4)/(C27*K28*O13),0) -> #REF! | P22: amps/cm² | R22: Numero de Fios Paralelos Sn S1 | S22: =S21/G12 -> #REF! | T22: fios | V22: I lm máx | W22: =W21+(W20/2) -> 0.6 | X22: A
B23: ∆ I Lm | C23: 20 | D23: % | F23: I Lm mín | G23: =G19-(G20/2) -> 2.682 | H23: A | N23: Primary Area Apw(B) | O23: =K13/O22 -> #REF! | P23: cm² | R23: Numero de Fios Paralelos Sn S1 | S23: =ROUND(S22,0) -> #REF! | T23: fios | V23: ∆ ic | W23: =G28*G31 -> 7692.8571 | X23: A
B24: Frequência | C24: 25 | D24: kH | F24: I Lm máx | G24: =G19+(G20/2) -> 3.278 | H24: A | J24: Dados Iniciais para Escolha do Indutor Acoplado | N24: Nº de Fios em Paralelo Primario Snp | O24: =O23/G12 -> #REF! | P24: fios | R24: Novo S1 micro Ohm | S24: =IF(S23=0,0,ROUND(G13/S23,0)) -> #REF! | T24: uΩ/cm 22º C | V24: ∆ V0, ESR | W24: =C26%*C12 -> #REF! | X24: V
B25: Frequência | C25: =C24*1000 -> 25000 | D25: H | F25: Modo de Operação Segundo Hart | J25: Capacidade de manuseio Energia | K25: =ROUND((K8*(K12^2))/2,7) -> 32.506694 | L25: W*s | N25: Nº de Fios em Paralelo Primario Snp | O25: =ROUND(O24,0) -> #REF! | P25: fios | R25: Nova resistencia do Secundario S1 | S25: =ROUND(O10*S18*S24*10^-6,4) -> #REF! | T25: Ω | V25: rc | W25: =W24/W23 -> #REF! | X25: Ω
B26: Regulação | C26: =Dados_Projeto!#REF! -> #REF! | D26: % | F26: =IF(G23<0,"Descontínuo","Contínuo") -> Contínuo | J26: Condições Eletricas Ke | K26: =ROUND((0.145*C20*(C27^2)*10^-4),7) -> 2.58e-05 | N26: Área destinada ao Primario | O26: =O12/2 -> 0.825 | P26: cm² | R26: Perda de Cobre do Secundario S1 | S26: =ROUND((S20^2)*S25,4) -> #REF! | T26: W | V26: C | W26: =(10^-5)/W25 -> #REF! | X26: F
B27: Bmax | C27: 0.25 | D27: Tesla | F27: Definindo o Núcleo | J27: Geometria do Núcleo Kg | K27: =(K25^2)/(K26) -> 40956790 | L27: cm⁵ | N27: Nº de Espiras do Primario Np | O27: =(K28*O26)/(O25*G12) -> #REF! | P27: voltas | V27: C Comercial | W27: =INDEX(Tabela3[Em Faraday],MATCH("Sim",Tabela3[C_TCC],0)) -> 3.3e-05 | X27: F
B28: Tipo da Condução | C28: =Dados_Projeto!D30 -> Contínuo | F28: Al do Núcleo | G28: 3590 | H28: nH/Np² | J28: Ku utilizado no Livro Exemplo | K28: =IF(C29="Toroidal",_xlfn.XLOOKUP(G11,AWG!B6:B40,AWG!AC6:AC40,"",0,1),_xlfn.XLOOKUP(G11,AWG!B6:B40,AWG!AB6:AB40,"",0,1)) -> #REF! | N28: Nº de Espiras do Primario Np | O28: =ROUND(O27,0) -> #REF! | P28: voltas | V28: ∆ Vout / Vo | W28: =ROUND(C21/(C13*(W27)*C25),4) -> 0.8485
B29: Tipo do Ferrite | C29: =Dados_Projeto!D31 -> Toroidal | F29: Lm | G29: =G22*1000 -> 564000 | H29: nH | J29: Fator Multiplicador Acima de 100 kHz | K29: =IF(C24>=100,1.35,1) -> 1 | N29: Espaçamento Necessario Ig | O29: =ROUND(((0.4*PI()*(O28^2)*O11*(10^-8))/K8)-(O7/O16),4) -> #REF! | P29: cm | V29: ∆ Vout / Vo | W29: =W28*100 -> 84.85 | X29: %
B30: Calculos Periodo | F30: Número de Voltas Primário | G30: =ROUNDDOWN(SQRT(G29/G28),0) -> 12 | H30: Voltas | J30: Geometria do Núcleo Kg final | K30: =IF(C24>=100,K27*K29,K27*K29) -> 40956790 | L30: cm⁵ | N30: Espaçamento Necessario Ig em mils | O30: =ROUND(O29*393.7,0) -> #REF! | V30: Teste ∆ Vout / Vo | W30: =IF(W29>C26,"Real > Proj","Real < Proj") -> #REF!
B31: Periodo T | C31: =1/C25 -> 4e-05 | D31: s | F31: Número de Voltas Secundáio | G31: =G30*G17 -> 2.1428571 | H31: Voltas | J31: Geometria do Núcleo Kg escolhida | K31: =O14 -> 0.07299 | L31: cm⁵ | N31: Espalhamento de Fluxo F | O31: =ROUND(1+(O29/SQRT(K28))*LN((2*O17)/O29),1) -> #REF!
B32: Ton | C32: =C21*C31 -> 2.8e-05 | D32: s | F32: Qntd Fios | G32: 3 | H32: Fios | J32: % do Projeto em Cima do Indutor | K32: =(K30/K31)*100 -> 5.6112878e+10 | L32: % | N32: Novo Número de Espiras | O32: =SQRT((O29*K8)/(0.4*PI()*O11*O31*10^-8)) -> #REF! | P32: voltas | V32: Calculos Gerais do Cirucito Snubber Toff
B33: Toff | C33: =C31*(1-C21-C22) -> #REF! | D33: s | F33: Qual Fio | G33: 20 | H33: AWG | J33: Geometria do Núcleo Kg final | K33: =IF(K30>K31,"Proj > Indutor","Proj < Indutor") -> Proj > Indutor | N33: Novo Número de Espiras true N np | O33: =ROUND(O32,0) -> #REF! | P33: voltas | V33: Parametro | W33: Valor | X33: Unidade
B34: T perdido Well | C34: =C31-(C33+C32) -> #REF! | D34: s | N34: Densidade do Fluxo do Primario Bpk | O34: =ROUND((0.4*PI()*O33*O31*K12*10^-4)/(O29+O7/O16),3) -> #REF! | P34: Tesla | V34: V máx B Transistor | W34: 75 | X34: V | Y34: *pegar no datasheet
J35: Energia | K35: Lm | N35: Nova resistencia do Primario p/ Fio | O35: =ROUND(G13/O25,0) -> #REF! | P35: uΩ/cm 22º C | V35: Taxa Segurança Vsn | W35: 20 | X35: %
J36: =SQRT(K31*K26) -> 0.0013722762 | K36: =((J36*2)/(K21^2)) -> 5.9604935e-09 | N36: Nova resistencia do Primario Rp | O36: =ROUND(O10*O33*O35*10^-6,4) -> #REF! | P36: Ω | V36: Vsn sem a Taxa | W36: =W34*(100%-W35%) -> 60 | X36: V
F37: Modo de Operação Segundo Hart | N37: Perda de Cobre do Primario | O37: =ROUND(K13^2*O36,4) -> #REF! | P37: W | V37: ∆ V sn | W37: 5 | X37: % | Y37: 5 a 10 segundo o filchild
B38: Vdc min | C38: =C6 -> 12 | F38: =IF(G32<0,"Descontínuo","Contínuo") -> Contínuo | V38: V ro (Dissipada) | W38: =(C11+C12)*G18 -> 31.92 | X38: V
B39: Vro | C39: =C12 -> 5 | V39: Potencia Dissipada | W39: =(1/2)*C25*G21*(K21^2)*(W36/(W36-W38)) -> 6933403.7 | X39: W
B40: Ipk | C40: =K21 -> 678.57 | V40: R snubber | W40: =ROUND((W36^2)/W39,2) -> 0 | X40: Ω
...

Sheet Calculo_Flyback_MCLYMAN
A1: AAAAAA | E1: AAAAAA | F1: aaaaaaaaa | G1: aaaaaa | H1: aaaaaaa | I1: AAAAAA | M1: AAAAAA | Q1: AAAAAA | U1: AAAAAA
B2: Dados Basicos do Projeto | F2: Cálculo do Fio Mínimo Bobina | J2: Método Contínuo (MCLYMAN) | N2: Dados da Toroide Utilizada | R2: Calculos do Transformador Secundario 1 (Vout1) | V2: Calculos Gerais do Transformador
B3: Parametro | C3: Valor | D3: Unidade | F3: Parametro | G3: Valor | H3: Unidade | J3: Correntes do Primário | N3: Core Number | O3: EFD-20 | R3: Numero de Espiras Secundario 1 Ns1 | S3: =(O30*(C12+C11)*(1-C21-C22))/(C6*C21) -> 3.2 | T3: Voltas | V3: Espiras Primario | W3: =O22*O30 -> 48 | X3: Voltas
B4: V in(max) | C4: 32 | D4: V | F4: Profundidade de Penetração | G4: =6.62/SQRT(C24) -> 0.020934278 | H4: cm | J4: Parametro | K4: Valor | L4: Unidade | N4: Fabricante | O4: Philips | R4: Numero de Espiras Secundario 1 Ns1 | S4: =ROUND(S3,0) -> 3 | T4: Voltas | V4: Espiras S1 Secundario | W4: =S4*S9 -> 24 | X4: Voltas
B5: V in rms | C5: 28 | D5: V | F5: Diametro do Fio | G5: =2*G4 -> 0.041868556 | H5: cm | J5: D min | K5: =(C6/C4)*C21 -> 0.375 | N5: Material | O5: 3C85 | R5: Corrente de Pico Is1(pk) | S5: =(2*C14)/(1-C21-C22) -> 10 | T5: A | V5: Espiras S2 Secundario | W5: =S16*S21 -> 14 | X5: Voltas
B6: V in(min) | C6: 24 | D6: V | F6: Área do Fio (Aw) | G6: =ROUND((PI()*G5^2)/4,5) -> 0.00138 | H6: cm² | J6: T off (max) | K6: =C30*(1-K5) -> 6.25e-06 | L6: s | N6: MPL | O6: 4.7 | P6: cm | R6: Corrente de RMS Is1(rms) | S6: =ROUND(S5*SQRT((1-C21-C22)/3),2) -> 3.65 | T6: A | V6: Total Espiras | W6: =SUM(W3:W5) -> 86 | X6: Voltas
B7: R in rms | C7: 28 | D7: Ohm | F7: Fio Mínimo Escolhido | J7: Lm rms Calc 1 | K7: =ROUND((((C4*K5)^2)*C30)/(2*C10),9) -> 3.5019e-05 | L7: H | N7: Core Weight | O7: 7 | P7: gramas | R7: Area do Fio Secundario Asw1(b) | S7: =ROUND(S6/O19,5) -> 0.00995 | T7: cm² | V7: Ku total | W7: =W6*G12/O11 -> 0.21972056 | X7: constante
B8: I in (max) | C8: 0.86 | D8: A | F8: Área do Fio (AWG) Mínimo | G8: =INDEX(AWG!O:O,MATCH("Sim",AWG!S:S,0)) -> 0.00128 | H8: cm² | J8: Lm rms Contínuo | K8: =IF(C27="Contínuo",G29,K7) -> 3.5019e-05 | L8: H | N8: Copper Weight Wteu | O8: 6.8 | P8: gramas | R8: Numero de Fios Paralelos Sn S1 | S8: =S7/G12 -> 7.7734375 | T8: fios | V8: Perda Total de Cobre | W8: =S12+S24+O34 -> 0.0937 | X8: W
B9: n eficiência | C9: 90 | D9: % | F9: Fio AWG | G9: =INDEX(AWG!B:B,MATCH("Sim",AWG!S:S,0)) -> 26 | H9: AWG | J9: Lm rms | K9: =K8*1000000 -> 35.019 | L9: uH | N9: MLT | O9: 3.8 | P9: cm | R9: Numero de Fios Paralelos Sn S1 | S9: =ROUND(S8,0) -> 8 | T9: fios | V9: Regulação Alpha | W9: =W8/C20 -> 0.0050648649 | X9: %
B10: P in rms | C10: 20.56 | D10: W | F10: Resistência | G10: =INDEX(AWG!E:E,MATCH("Sim",AWG!S:S,0)) -> 1345 | H10: uΩ/cm 22º C | J10: ∆ Lm rms | K10: =ROUND((C30*C6*C21)/K8,2) -> 3.43 | L10: A | N10: Iron Area Ac | O10: 0.31 | P10: cm² | R10: Novo S1 micro Ohm | S10: =ROUND(G13/S9,0) -> 168 | T10: uΩ/cm 22º C | V10: Densidade de Fluxo Ac, Bac | W10: =(0.4*PI()*O30*O28*(K12/2)*10^-4)/(O26+(O6/O15)) -> 0.11156485 | X10: Testa
B11: V diodo | C11: 1 | D11: V | F11: Fio AWG Escolhido | G11: =G9 -> 26 | H11: AWG | J11: I in (max) | K11: =C8 -> 0.86 | L11: A | N11: Window Area Wa | O11: 0.501 | P11: cm² | R11: Nova resistencia do Secundario S1 | S11: =O9*S4*S10*10^-6 -> 0.0019152 | T11: Ω | V11: Perda em Watts por Kilograma WK | W11: =ROUND(4.855*(10^-5)*(C24^1.63)*(W10^2.62),1) -> 21.9 | X11: Watts/grama
B12: V out (1) | C12: 5 | D12: V | F12: Área do Fio (AWG) Mínimo | G12: =_xlfn.XLOOKUP(G11,AWG!B6:B40,AWG!O6:O40,"",0,1) -> 0.00128 | H12: cm² | J12: I p(pk) primary | K12: =IF(C27="Contínuo",ROUND((C8/C21)+(K10/2),2),K21) -> 3.43 | L12: A | N12: Area Product Ap | O12: 0.155 | P12: cm⁴ | R12: Perda de Cobre do Secundario S1 | S12: =ROUND((S6^2)*S11,4) -> 0.0255 | T12: W | V12: Perda no núcleo | W12: =W11*O7*10^-3 -> 0.1533 | X12: W
B13: R out (1) | C13: 2.5 | D13: Ohm | F13: Resistência | G13: =_xlfn.XLOOKUP(G11,AWG!B6:B40,AWG!E6:E40,"",0,1) -> 1345 | H13: uΩ/cm 22º C | J13: I p(rms - pk) primary | K13: =IF(C27="Contínuo",ROUND(K12*SQRT((C31/(3*C30))),2),K22) -> 1.4 | L13: A | N13: Core Geometry Kg | O13: 0.00506 | P13: cm⁵ | V13: Perda do Núcleo + Cobre | W13: =W12+W8 -> 0.247 | X13: W
B14: I out (1) | C14: 2 | D14: A | N14: Surface Area At | O14: 13.3 | P14: cm | R14: Calculos do Transformador Secundario 2 (Vout2) | V14: Densidade de Potencia tridente | W14: =W13/O14 -> 0.018571429 | X14: W/cm²
B15: P out (1) | C15: 12 | D15: W | F15: Teste do Modo de Operação | J15: Método Descontínuo (MCLYMAN) | N15: Core Permeability | O15: 2500 | R15: Numero de Espiras Secundario 1 Ns1 | S15: =(O30*(C16+C11)*(1-C21-C22))/(C6*C21) -> 6.9333333 | T15: Voltas | V15: Elevação de Temperatura | W15: =ROUND(450*(W14^0.826),1) -> 16.7 | X15: ºC
B16: V out (2) | C16: 12 | D16: V | F16: Parametro | G16: Valor | H16: Unidade | J16: Correntes do Primário | N16: Winding Leangth G | O16: 1.54 | P16: cm | R16: Numero de Espiras Secundario 1 Ns1 | S16: =ROUND(S15,0) -> 7 | T16: Voltas
B17: R out (2) | C17: 24 | D17: Ohm | F17: I Lm | G17: =ROUND((C12^2)/(C5*C21*C13),2) -> 0.71 | H17: A | J17: Parametro | K17: Valor | L17: Unidade | R17: Corrente de Pico Is1(pk) | S17: =(2*C18)/(1-C21-C22) -> 2.5 | T17: A | V17: Calculos Gerais do Capacitor Out
B18: I out (2) | C18: 0.5 | D18: A | F18: ∆ I Lm | G18: =ROUND((C5*C21)/(K7*C24),2) -> 4 | H18: A | J18: L p max | K18: =ROUND((C7*C30*C21^2)/2,9) -> 3.5e-05 | L18: H | N18: Calculos do Transformador Primario | R18: Corrente de RMS Is1(rms) | S18: =ROUND(S17*SQRT((1-C21-C22)/3),3) -> 0.913 | T18: A | V18: I Lm | W18: =G25 -> 0.71 | X18: A
B19: P out (2) | C19: 6.5 | D19: W | F19: I Lm mín | G19: =G17-(G18/2) -> -1.29 | H19: A | J19: L p max | K19: =K18*1000000 -> 35 | L19: uH | N19: Energia J | O19: =ROUNDUP((2*(K25)*10^4)/(C26*K28*O12),0) -> 367 | P19: amps/cm² | R19: Area do Fio Secundario Asw1(b) | S19: =ROUND(S18/O19,5) -> 0.00249 | T19: cm² | V19: ∆ I Lm | W19: =ROUND((C5*C21)/(K8*C24),2) -> 4 | X19: A
B20: P out max | C20: 18.5 | D20: W | F20: I Lm máx | G20: =G17+(G18/2) -> 2.71 | H20: A | J20: I in (max) | K20: =C8 -> 0.86 | L20: A | N20: Primary Area Apw(B) | O20: =ROUND(K13/O19,5) -> 0.00381 | P20: cm² | R20: Numero de Fios Paralelos Sn S1 | S20: =S19/G12 -> 1.9453125 | T20: fios | V20: I lm máx | W20: =W19+(W18/2) -> 4.355 | X20: A
B21: D (Max) | C21: 0.5 | F21: Modo de Operação Segundo Hart | J21: I p(pk) primary | K21: =ROUND((2*C20*C30)/((C9%)*C6*C31),2) -> 3.43 | L21: A | N21: Nº de Fios em Paralelo Primario Snp | O21: =O20/G12 -> 2.9765625 | P21: fios | R21: Numero de Fios Paralelos Sn S1 | S21: =ROUND(S20,0) -> 2 | T21: fios | V21: ∆ ic | W21: =G28*G31 -> 0.38589286 | X21: A
B22: D (well) | C22: 0.1 | F22: =IF(G19<0,"Descontínuo","Contínuo") -> Descontínuo | J22: I p(rms - pk) primary | K22: =ROUND(K21*SQRT((C31/(3*C30))),2) -> 1.4 | L22: A | N22: Nº de Fios em Paralelo Primario Snp | O22: =ROUND(O21,0) -> 3 | P22: fios | R22: Novo S1 micro Ohm | S22: =IF(S21=0,0,ROUND(G13/S21,0)) -> 673 | T22: uΩ/cm 22º C | V22: ∆ V0, ESR | W22: =C25%*C12 -> 0.1 | X22: V
B23: Frequência | C23: 100 | D23: kH | F23: Caso Escolha Método Contínuo | N23: Área destinada ao Primario | O23: =O11/2 -> 0.2505 | P23: cm² | R23: Nova resistencia do Secundario S1 | S23: =ROUND(O9*S16*S22*10^-6,4) -> 0.0179 | T23: Ω | V23: rc | W23: =W22/W21 -> 0.25913929 | X23: Ω
B24: Frequência | C24: 100000 | D24: H | F24: % Acima de 0 I LM min | G24: 140 | H24: % | J24: Dados Iniciais para Escolha do Indutor Acoplado | N24: Nº de Espiras do Primario Np | O24: =(K28*O23)/(O22*G12) -> 18.917969 | P24: voltas | R24: Perda de Cobre do Secundario S1 | S24: =ROUND((S18^2)*S23,4) -> 0.0149 | T24: W | V24: C | W24: =(10^-5)/W23 -> 3.8589286e-05 | X24: F
B25: Regulação | C25: 2 | D25: % | F25: I Lm | G25: =ROUND((C12^2)/(C5*C21*C13),2) -> 0.71 | H25: A | J25: Capacidade de manuseio Energia | K25: =ROUND((K8*(K12^2))/2,7) -> 0.000206 | L25: W*s | N25: Nº de Espiras do Primario Np | O25: =ROUND(O24,0) -> 19 | P25: voltas | V25: C Comercial | W25: =INDEX(Tabela3[Em Faraday],MATCH("Sim",#REF!,0)) -> #REF! | X25: F
B26: Bmax | C26: 0.25 | D26: Tesla | F26: ∆ I Lm | G26: =G24%*G19*-1 -> 1.806 | H26: A | J26: Condições Eletricas Ke | K26: =ROUND((0.145*C20*(C26^2)*10^-4),7) -> 1.68e-05 | N26: Espaçamento Necessario Ig | O26: =ROUND(((0.4*PI()*(O25^2)*O10*(10^-8))/K8)-(O6/O15),4) -> 0.0383 | P26: cm | V26: ∆ Vout / Vo | W26: =ROUND(C21/(C13*(W25)*C24),4) -> #REF!
B27: Tipo da Condução | C27: Descontínuo | F27: I lm mín | G27: =G26-(G25/2) -> 1.451 | H27: A | J27: Geometria do Núcleo Kg | K27: =(K25^2)/(K26) -> 0.0025259524 | L27: cm⁵ | N27: Espaçamento Necessario Ig em mils | O27: =ROUND(O26*393.7,0) -> 15 | V27: ∆ Vout / Vo | W27: =W26*100 -> #REF! | X27: %
B28: Tipo do Ferrite | C28: Laminado | F28: I lm máx | G28: =G26+(G25/2) -> 2.161 | H28: A | J28: Ku utilizado no Livro Exemplo | K28: =IF(C28="Toroidal",_xlfn.XLOOKUP(G11,AWG!B6:B40,AWG!AC6:AC40,"",0,1),_xlfn.XLOOKUP(G11,AWG!B6:B40,AWG!AB6:AB40,"",0,1)) -> 0.29 | N28: Espalhamento de Fluxo F | O28: =ROUND(1+(O26/SQRT(K28))*LN((2*O16)/O26),1) -> 1.3 | V28: Teste ∆ Vout / Vo | W28: =IF(W27>C25,"Real > Proj","Real < Proj") -> #REF!
B29: Calculos Periodo | F29: Lm | G29: =ROUND((C5*C21)/(G26*C24),9) -> 7.7519e-05 | H29: H | J29: Fator Multiplicador Acima de 100 kHz | K29: =IF(C23>=100,1.35,1) -> 1.35 | N29: Novo Número de Espiras | O29: =SQRT((O26*K8)/(0.4*PI()*O10*O28*10^-8)) -> 16.273981 | P29: voltas
B30: Periodo T | C30: =1/C24 -> 1e-05 | D30: s | F30: N2/N1 | G30: =ROUND((C5/C12)*((1-C21)/C21),2) -> 5.6 | H30: =W4/W3 -> 0.5 | J30: Geometria do Núcleo Kg final | K30: =IF(C23>=100,K27*K29,K27*K29) -> 0.0034100357 | L30: cm⁵ | N30: Novo Número de Espiras true N np | O30: =ROUND(O29,0) -> 16 | P30: voltas
B31: Ton | C31: =C21*C30 -> 5e-06 | D31: s | F31: N1/N2 | G31: =1/G30 -> 0.17857143 | H31: =1/H30 -> 2 | J31: Geometria do Núcleo Kg escolhida | K31: =O13 -> 0.00506 | L31: cm⁵ | N31: Densidade do Fluxo do Primario Bpk | O31: =ROUND((0.4*PI()*O30*O28*K12*10^-4)/(O26+O6/O15),3) -> 0.223 | P31: Tesla
B32: Toff | C32: =C30*(1-C21-C22) -> 4e-06 | D32: s | F32: Modo de Operação Segundo Hart | J32: % do Projeto em Cima do Indutor | K32: =(K30/K31)*100 -> 67.39201 | L32: % | N32: Nova resistencia do Primario p/ Fio | O32: =ROUND(G13/O22,0) -> 448 | P32: uΩ/cm 22º C
B33: T perdido Well | C33: =C30-(C32+C31) -> 1e-06 | D33: s | F33: =IF(G27<0,"Descontínuo","Contínuo") -> Contínuo | J33: Geometria do Núcleo Kg final | K33: =IF(K30>K31,"Proj > Indutor","Proj < Indutor") -> Proj < Indutor | N33: Nova resistencia do Primario Rp | O33: =ROUND(O9*O30*O32*10^-6,4) -> 0.0272 | P33: Ω
N34: Perda de Cobre do Primario | O34: =ROUND(K13^2*O33,4) -> 0.0533 | P34: W

Sheet Toroide_Iron_Powder
A1: Part No. | B1: OD (cm) | C1: ID (cm) | D1: HT (cm) | E1: AC (cm) | F1: G toroide | H1: Part No. | I1: Ww (g) | J1: We (g) | K1: MLT (cm) | L1: MPL (cm) | M1: Wa (cm²) | N1: Coluna1 | O1: Ac (cm²) | P1: W2 (cm²) | Q1: Ap (cm⁴) | R1: Kg | S1: Ae (cm²) | T1: AL (mh/1k)
A2: T20-26 | B2: 0.508 | C2: 0.224 | D2: 0.178 | E2: =((B2-C2)*D2)/2 -> 0.025276 | F2: =(Dimensoes_Toroide_Iron_Powder[[#This Row],[OD (cm)]]-Dimensoes_Toroide_Iron_Powder[[#This Row],[ID (cm)]])/2 -> 0.142 | H2: T20-26 | I2: 0.1 | J2: 0.19 | K2: 0.7 | L2: 1.15 | M2: 1.713 | O2: 0.023 | P2: 0.039 | Q2: 0.0009 | R2: 1e-05 | S2: 1.2 | T2: 18.5
A3: T25-26 | B3: 0.648 | C3: 0.305 | D3: 0.244 | E3: =((B3-C3)*D3)/2 -> 0.041846 | F3: =(Dimensoes_Toroide_Iron_Powder[[#This Row],[OD (cm)]]-Dimensoes_Toroide_Iron_Powder[[#This Row],[ID (cm)]])/2 -> 0.1715 | H3: T25-26 | I3: 0.24 | J3: 0.39 | K3: 0.9 | L3: 1.5 | M3: 1.973 | O3: 0.037 | P3: 0.073 | Q3: 0.0027 | R3: 3.8e-05 | S3: 2 | T3: 24.5
